<?xml version="1.0" ?>
<robot name="drone_urdf_export_v4">

<material name="silver">
  <color rgba="0.700 0.700 0.700 1.000"/>
</material>

<link name="base_link">
  <inertial>
    <origin xyz="-0.0001888883906475944 6.4204395809341846e-06 0.007418143508515953" rpy="0 0 0"/>
    <mass value="0.25021955564014492"/>
    <inertia ixx="0.0070489199931757585" iyy="0.007050063776988111" izz="0.013721819831554363" ixy="1.9619262831054358e-07" iyz="7.827449880984244e-08" ixz="-1.5752407683397344e-06"/>
  </inertial>
  <visual>
    <origin xyz="0 0 0" rpy="0 0 0"/>
    <geometry>
      <mesh filename="meshes/base_link.stl" scale="0.001 0.001 0.001"/>
    </geometry>
    <material name="silver"/>
    <material/>
  </visual>
  <collision>
    <origin xyz="0 0 0" rpy="0 0 0"/>
    <geometry>
      <mesh filename="meshes/base_link.stl" scale="0.001 0.001 0.001"/>
    </geometry>
  </collision>
</link>

<link name="wing_a_link1">
  <inertial>
    <origin xyz="0.19929168941472217 0.01877722861244028 -0.02684188940360497" rpy="0 0 0"/>
    <mass value="0.04060892541828371"/>
    <inertia ixx="5.3283357273089454e-05" iyy="0.0007293374996617794" izz="0.0006781877865775841" ixy="-4.628149343882811e-06" iyz="-2.2555674462078508e-06" ixz="-3.264519072643849e-05"/>
  </inertial>
  <visual>
    <origin xyz="-0.0 0.024474 -0.030885" rpy="0 0 0"/>
    <geometry>
      <mesh filename="meshes/base_link1wing_a_link1.stl" scale="0.001 0.001 0.001"/>
    </geometry>
    <material name="silver"/>
    <material/>
  </visual>
  <collision>
    <origin xyz="-0.0 0.024474 -0.030885" rpy="0 0 0"/>
    <geometry>
      <mesh filename="meshes/base_link1wing_a_link1.stl" scale="0.001 0.001 0.001"/>
    </geometry>
  </collision>
</link>

<link name="wing_b_link1">
  <inertial>
    <origin xyz="-0.11590729596618668 0.1632030514900452 -0.026956607960014478" rpy="0 0 0"/>
    <mass value="0.04060892541828371"/>
    <inertia ixx="0.0005563158691602971" iyy="0.00022630498777457273" izz="0.000678187786577575" ixy="0.00029505410549309505" iyz="-2.714378075738013e-05" ixz="1.8275974071584362e-05"/>
  </inertial>
  <visual>
    <origin xyz="-0.021195 -0.012237 -0.030885" rpy="0 0 0"/>
    <geometry>
      <mesh filename="meshes/base_link1wing_b_link1.stl" scale="0.001 0.001 0.001"/>
    </geometry>
    <material name="silver"/>
    <material/>
  </visual>
  <collision>
    <origin xyz="-0.021195 -0.012237 -0.030885" rpy="0 0 0"/>
    <geometry>
      <mesh filename="meshes/base_link1wing_b_link1.stl" scale="0.001 0.001 0.001"/>
    </geometry>
  </collision>
</link>

<link name="wing_c_link1">
  <inertial>
    <origin xyz="-0.08338439344853543 -0.18198028010249048 -0.02695660796001445" rpy="0 0 0"/>
    <mass value="0.04060892541828371"/>
    <inertia ixx="0.0005643320589689177" iyy="0.000218288797965951" izz="0.0006781877865775806" ixy="-0.0002904259561492123" iyz="2.939934820358796e-05" ixz="1.4369216654853953e-05"/>
  </inertial>
  <visual>
    <origin xyz="0.021195 -0.012237 -0.030885" rpy="0 0 0"/>
    <geometry>
      <mesh filename="meshes/base_link1wing_c_link1.stl" scale="0.001 0.001 0.001"/>
    </geometry>
    <material name="silver"/>
    <material/>
  </visual>
  <collision>
    <origin xyz="0.021195 -0.012237 -0.030885" rpy="0 0 0"/>
    <geometry>
      <mesh filename="meshes/base_link1wing_c_link1.stl" scale="0.001 0.001 0.001"/>
    </geometry>
  </collision>
</link>

<link name="wing_a_link1motor_a_link1">
  <inertial>
    <origin xyz="-4.459279808188832e-07 3.9695907997630634e-08 0.00795147250991321" rpy="0 0 0"/>
    <mass value="0.060164910276644738"/>
    <inertia ixx="2.814681256508187e-07" iyy="2.8146835653040415e-07" izz="2.8952392484339357e-07" ixy="8.16615800690484e-14" iyz="1.1145137703316661e-13" ixz="-6.324760051627798e-13"/>
  </inertial>
  <visual>
    <origin xyz="-0.317737 -1.8e-05 -0.04" rpy="0 0 0"/>
    <geometry>
      <mesh filename="meshes/base_link1wing_a_link1motor_a_link1.stl" scale="0.001 0.001 0.001"/>
    </geometry>
    <material name="silver"/>
    <material/>
  </visual>
  <collision>
    <origin xyz="-0.317737 -1.8e-05 -0.04" rpy="0 0 0"/>
    <geometry>
      <mesh filename="meshes/base_link1wing_a_link1motor_a_link1.stl" scale="0.001 0.001 0.001"/>
    </geometry>
  </collision>
</link>

<link name="wing_a_link1motor_a_link1prop_a_link1">
  <inertial>
    <origin xyz="-4.575744744772514e-07 2.9767732054561164e-08 -0.0011797680042403627" rpy="0 0 0"/>
    <mass value="0.0103131751235644734"/>
    <inertia ixx="8.978921575554907e-08" iyy="8.978944692405663e-08" izz="1.7734403043569917e-07" ixy="8.161035293749475e-14" iyz="-1.155970609218585e-14" ixz="2.6361528791037786e-15"/>
  </inertial>
  <visual>
    <origin xyz="-0.317737 -1.8e-05 -0.0557" rpy="0 0 0"/>
    <geometry>
      <mesh filename="meshes/base_link1wing_a_link1motor_a_link1prop_a_link1.stl" scale="0.001 0.001 0.001"/>
    </geometry>
    <material name="silver"/>
    <material/>
  </visual>
  <collision>
    <origin xyz="-0.317737 -1.8e-05 -0.0557" rpy="0 0 0"/>
    <geometry>
      <mesh filename="meshes/base_link1wing_a_link1motor_a_link1prop_a_link1.stl" scale="0.001 0.001 0.001"/>
    </geometry>
  </collision>
</link>

<link name="wing_b_link1motor_b_link1">
  <inertial>
    <origin xyz="1.0012905291012508e-07 -9.231065967174601e-08 0.00795175395350372" rpy="0 0 0"/>
    <mass value="0.060164910276644738"/>
    <inertia ixx="2.814683695315603e-07" iyy="2.8146811264980484e-07" izz="2.89523924843502e-07" ixy="5.91430658787584e-14" iyz="-6.03465994081058e-13" ixz="2.1971829330990136e-13"/>
  </inertial>
  <visual>
    <origin xyz="0.158884 -0.275159 -0.039885" rpy="0 0 0"/>
    <geometry>
      <mesh filename="meshes/base_link1wing_b_link1motor_b_link1.stl" scale="0.001 0.001 0.001"/>
    </geometry>
    <material name="silver"/>
    <material/>
  </visual>
  <collision>
    <origin xyz="0.158884 -0.275159 -0.039885" rpy="0 0 0"/>
    <geometry>
      <mesh filename="meshes/base_link1wing_b_link1motor_b_link1.stl" scale="0.001 0.001 0.001"/>
    </geometry>
  </collision>
</link>

<link name="wing_b_link1motor_b_link1prop_b_link1">
  <inertial>
    <origin xyz="1.145503522037572e-07 -9.743273093887339e-08 -0.0011794865606498742" rpy="0 0 0"/>
    <mass value="0.0103131751235644734"/>
    <inertia ixx="8.978945980853907e-08" iyy="8.978920287104885e-08" izz="1.7734403043572627e-07" ixy="5.929371577062525e-14" iyz="8.062828697882538e-15" ixz="8.69292464888375e-15"/>
  </inertial>
  <visual>
    <origin xyz="0.158884 -0.275159 -0.055585" rpy="0 0 0"/>
    <geometry>
      <mesh filename="meshes/base_link1wing_b_link1motor_b_link1prop_b_link1.stl" scale="0.001 0.001 0.001"/>
    </geometry>
    <material name="silver"/>
    <material/>
  </visual>
  <collision>
    <origin xyz="0.158884 -0.275159 -0.055585" rpy="0 0 0"/>
    <geometry>
      <mesh filename="meshes/base_link1wing_b_link1motor_b_link1prop_b_link1.stl" scale="0.001 0.001 0.001"/>
    </geometry>
  </collision>
</link>

<link name="wing_c_link1motor_c_link1">
  <inertial>
    <origin xyz="3.45798928047536e-07 5.2614746670620605e-08 0.007951753953503726" rpy="0 0 0"/>
    <mass value="0.060164910276644738"/>
    <inertia ixx="2.8146822808963485e-07" iyy="2.814682540917574e-07" izz="2.89523924843502e-07" ixy="-1.4080463140928035e-13" iyz="4.920146186087812e-13" ixz="4.1275773218166917e-13"/>
  </inertial>
  <visual>
    <origin xyz="0.158853 0.275177 -0.039885" rpy="0 0 0"/>
    <geometry>
      <mesh filename="meshes/base_link1wing_c_link1motor_c_link1.stl" scale="0.001 0.001 0.001"/>
    </geometry>
    <material name="silver"/>
    <material/>
  </visual>
  <collision>
    <origin xyz="0.158853 0.275177 -0.039885" rpy="0 0 0"/>
    <geometry>
      <mesh filename="meshes/base_link1wing_c_link1motor_c_link1.stl" scale="0.001 0.001 0.001"/>
    </geometry>
  </collision>
</link>

<link name="wing_c_link1motor_c_link1prop_c_link1">
  <inertial>
    <origin xyz="3.430241224122721e-07 6.76649939967966e-08 -0.0011794865606498534" rpy="0 0 0"/>
    <mass value="0.0103131751235644734"/>
    <inertia ixx="8.97893184552878e-08" iyy="8.978934422431366e-08" izz="1.7734403043569917e-07" ixy="-1.4090406630102442e-13" iyz="3.4968840431810755e-15" ixz="-1.132907413985574e-14"/>
  </inertial>
  <visual>
    <origin xyz="0.158853 0.275177 -0.055585" rpy="0 0 0"/>
    <geometry>
      <mesh filename="meshes/base_link1wing_c_link1motor_c_link1prop_c_link1.stl" scale="0.001 0.001 0.001"/>
    </geometry>
    <material name="silver"/>
    <material/>
  </visual>
  <collision>
    <origin xyz="0.158853 0.275177 -0.055585" rpy="0 0 0"/>
    <geometry>
      <mesh filename="meshes/base_link1wing_c_link1motor_c_link1prop_c_link1.stl" scale="0.001 0.001 0.001"/>
    </geometry>
  </collision>
</link>

<joint name="Revolute 3" type="revolute">
  <origin xyz="0.0 -0.024474 0.030885" rpy="0 0 0"/>
  <parent link="base_link"/>
  <child link="wing_a_link1"/>
  <axis xyz="1.0 -0.0 0.0"/>
  <limit upper="1.570796" lower="-1.658063" effort="100" velocity="100"/>
</joint>
<transmission name="_Revolute 3_tran">
  <type>transmission_interface/SimpleTransmission</type>
  <joint name="_Revolute 3">
    <hardwareInterface>PositionJointInterface</hardwareInterface>
  </joint>
  <actuator name="Revolute 3_actr">
    <hardwareInterface>PositionJointInterface</hardwareInterface>
    <mechanicalReduction>1</mechanicalReduction>
  </actuator>
</transmission>

<joint name="Revolute 4" type="revolute">
  <origin xyz="0.021195 0.012237 0.030885" rpy="0 0 0"/>
  <parent link="base_link"/>
  <child link="wing_b_link1"/>
  <axis xyz="-0.5 0.866025 0.0"/>
  <limit upper="1.570796" lower="-1.570796" effort="100" velocity="100"/>
</joint>
<transmission name="Revolute 4_tran">
  <type>transmission_interface/SimpleTransmission</type>
  <joint name="Revolute 4">
    <hardwareInterface>PositionJointInterface</hardwareInterface>
  </joint>
  <actuator name="Revolute 4_actr">
    <hardwareInterface>PositionJointInterface</hardwareInterface>
    <mechanicalReduction>1</mechanicalReduction>
  </actuator>
</transmission>

<joint name="Revolute 5" type="revolute">
  <origin xyz="-0.021195 0.012237 0.030885" rpy="0 0 0"/>
  <parent link="base_link"/>
  <child link="wing_c_link1"/>
  <axis xyz="-0.5 -0.866025 0.0"/>
  <limit upper="1.570796" lower="-1.570796" effort="100" velocity="100"/>
</joint>
<transmission name="Revolute 5_tran">
  <type>transmission_interface/SimpleTransmission</type>
  <joint name="Revolute 5">
    <hardwareInterface>PositionJointInterface</hardwareInterface>
  </joint>
  <actuator name="Revolute 5_actr">
    <hardwareInterface>PositionJointInterface</hardwareInterface>
    <mechanicalReduction>1</mechanicalReduction>
  </actuator>
</transmission>

<joint name="wing_a_link1_Rigid 1" type="fixed">
  <origin xyz="0.317737 0.024492 0.009115" rpy="0 0 0"/>
  <parent link="wing_a_link1"/>
  <child link="wing_a_link1motor_a_link1"/>
</joint>

<joint name="wing_a_link1motor_a_link1_Revolute 7" type="continuous">
  <origin xyz="0.0 0.0 0.0157" rpy="0 0 0"/>
  <parent link="wing_a_link1motor_a_link1"/>
  <child link="wing_a_link1motor_a_link1prop_a_link1"/>
  <axis xyz="-0.0 -0.0 1.0"/>
</joint>
<transmission name="wing_a_link1motor_a_link1_Revolute 7_tran">
  <type>transmission_interface/SimpleTransmission</type>
  <joint name="wing_a_link1motor_a_link1_Revolute 7">
    <hardwareInterface>PositionJointInterface</hardwareInterface>
  </joint>
  <actuator name="wing_a_link1motor_a_link1_Revolute 7_actr">
    <hardwareInterface>PositionJointInterface</hardwareInterface>
    <mechanicalReduction>1</mechanicalReduction>
  </actuator>
</transmission>

<joint name="wing_b_link1_Rigid 2" type="fixed">
  <origin xyz="-0.180079 0.262922 0.009" rpy="0 0 0"/>
  <parent link="wing_b_link1"/>
  <child link="wing_b_link1motor_b_link1"/>
</joint>

<joint name="wing_b_link1motor_b_link1_Revolute 8" type="continuous">
  <origin xyz="0.0 0.0 0.0157" rpy="0 0 0"/>
  <parent link="wing_b_link1motor_b_link1"/>
  <child link="wing_b_link1motor_b_link1prop_b_link1"/>
  <axis xyz="0.0 -0.0 1.0"/>
</joint>
<transmission name="wing_b_link1motor_b_link1_Revolute 8_tran">
  <type>transmission_interface/SimpleTransmission</type>
  <joint name="wing_b_link1motor_b_link1_Revolute 8">
    <hardwareInterface>PositionJointInterface</hardwareInterface>
  </joint>
  <actuator name="wing_b_link1motor_b_link1_Revolute 8_actr">
    <hardwareInterface>PositionJointInterface</hardwareInterface>
    <mechanicalReduction>1</mechanicalReduction>
  </actuator>
</transmission>

<joint name="wing_c_link1_Rigid 1" type="fixed">
  <origin xyz="-0.137658 -0.287414 0.009" rpy="0 0 0"/>
  <parent link="wing_c_link1"/>
  <child link="wing_c_link1motor_c_link1"/>
</joint>

<joint name="wing_c_link1motor_c_link1_Revolute 9" type="continuous">
  <origin xyz="0.0 0.0 0.0157" rpy="0 0 0"/>
  <parent link="wing_c_link1motor_c_link1"/>
  <child link="wing_c_link1motor_c_link1prop_c_link1"/>
  <axis xyz="0.0 0.0 1.0"/>
</joint>
<transmission name="wing_c_link1motor_c_link1_Revolute 9_tran">
  <type>transmission_interface/SimpleTransmission</type>
  <joint name="wing_c_link1motor_c_link1_Revolute 9">
    <hardwareInterface>PositionJointInterface</hardwareInterface>
  </joint>
  <actuator name="wing_c_link1motor_c_link1_Revolute 9_actr">
    <hardwareInterface>PositionJointInterface</hardwareInterface>
    <mechanicalReduction>1</mechanicalReduction>
  </actuator>
</transmission>

</robot>
